Workbook

Sheet Assumptions
A1: June 2025 - May 2028
A3: SaaS PRICING ASSUMPTIONS | B3: Value | C3: Unit | D3: Notes
A4: Tier 1 Monthly Price | B4: 49 | C4: €/month | D4: Individual users
A5: Tier 1 Annual Price | B5: 499 | C5: €/year | D5: 15% discount from monthly
A6: Tier 2 Monthly Price | B6: 250 | C6: €/month | D6: Team license (5-10 seats)
A7: Tier 2 Annual Price | B7: 3000 | C7: €/year | D7: 20% discount from monthly
A9: PLG FUNNEL ASSUMPTIONS | B9: Value | C9: Unit | D9: Notes
A10: Initial Free Users | B10: 100 | C10: users | D10: Starting number at launch
A11: Free User Growth Rate (Y1) | B11: 0.15 | C11: monthly | D11: Year 1 growth rate
A12: Free User Growth Rate (Y2) | B12: 0.1 | C12: monthly | D12: Year 2 growth rate
A13: Free User Growth Rate (Y3) | B13: 0.07 | C13: monthly | D13: Year 3 growth rate
A14: Free-to-Trial Conversion | B14: 0.005 | C14: percentage | D14: Typical for open-source PLG
A15: Trial-to-Paid (Tier 1) | B15: 0.2 | C15: percentage | D15: Conversion to Tier 1
A16: Trial-to-Paid (Tier 2) | B16: 0.05 | C16: percentage | D16: Conversion to Tier 2
A17: Monthly Churn (Tier 1) | B17: 0.03 | C17: monthly | D17: Individual users (higher churn)
A18: Monthly Churn (Tier 2) | B18: 0.015 | C18: monthly | D18: Team licenses (lower churn)
A19: Billing Mix (Monthly) | B19: 0.6 | C19: percentage | D19: Portion choosing monthly billing
A20: Billing Mix (Annual) | B20: 0.4 | C20: percentage | D20: Portion choosing annual billing
A22: ENTERPRISE SOLUTION ASSUMPTIONS | B22: Value | C22: Unit | D22: Notes
A23: Billing Rates
A24: Daily Rate - Team Member | B24: 1200 | C24: €/day | D24: Billing rate for team member project
A26: Working Days per Month | B26: 21 | C26: days | D26: Standard working days
A28: Project Parameters
A29: Small Project Duration | B29: 3 | C29: months | D29: Typical duration for small projects
A30: Medium Project Duration | B30: 4.5 | C30: months | D30: Average duration for medium projects (3-6 months)
A31: Small Projects per Year | B31: 8 | C31: projects | D31: Annual capacity for small projects
A32: Medium Projects per Year | B32: 4 | C32: projects | D32: Annual capacity for medium projects
A33: Project Mix (Small) | B33: 67% | C33: projects | D33: Distribution between small and medium projects
A34: Project Mix (Medium) | B34: 33% | C34: projects | D34: Distribution between small and medium projects
A36: Team Composition
A37: Small Team - Engineers | B37: 2 | C37: people | D37: Engineers per small project
A38: Small Team - Product Managers | B38: 1 | C38: person | D38: PMs per small project
A39: Medium Team - Engineers | B39: 3 | C39: people | D39: Engineers per medium project
A40: Medium Team - Product Managers | B40: 1 | C40: person | D40: PMs per medium project
A41: Medium Team - Product Designers | B41: 1 | C41: person | D41: Designers per medium project
A43: Freelancer Costs
A44: Engineer Hourly Rate | B44: 40 | C44: €/hour | D44: Average freelance rate (€30-50 range)
A45: Product Manager Hourly Rate | B45: 45 | C45: €/hour | D45: Average freelance rate (€35-55 range)
A46: Product Designer Hourly Rate | B46: 40 | C46: €/hour | D46: Average freelance rate (€30-50 range)
A47: Hours per Day | B47: 8 | C47: hours | D47: Standard working day
...

Sheet Enterprise Solutions
A1: ENTERPRISE SOLUTION ASSUMPTIONS | B1: Value | C1: Unit | D1: Notes
A3: Billing Rates
A4: Daily Rate per Person | B4: 1200 | C4: €/day/person | D4: Billing rate per person (not per team)
A5: Working Days per Month | B5: 21 | C5: days | D5: Standard working days
A7: Project Parameters
A8: Small Project Duration | B8: 3 | C8: months | D8: Typical duration for small projects
A9: Medium Project Duration | B9: 4.5 | C9: months | D9: Average duration for medium projects (3-6 months)
A10: Small Projects per Year | B10: 8 | C10: projects | D10: Annual capacity for small projects
A11: Medium Projects per Year | B11: 4 | C11: projects | D11: Annual capacity for medium projects
A12: Project Mix (Small:Medium) | B12: 67% | C12: 33% | D12: Distribution between small and medium projects
A14: Team Composition
A15: Small Team - Engineers | B15: 2 | C15: people | D15: Engineers per small project
A16: Small Team - Product Managers | B16: 1 | C16: person | D16: PMs per small project
A17: Medium Team - Engineers | B17: 3 | C17: people | D17: Engineers per medium project
A18: Medium Team - Product Managers | B18: 1 | C18: person | D18: PMs per medium project
A19: Medium Team - Product Designers | B19: 1 | C19: person | D19: Designers per medium project
A21: Freelancer Costs
A22: Engineer Hourly Rate | B22: 40 | C22: €/hour | D22: Average freelance rate (€30-50 range)
A23: Product Manager Hourly Rate | B23: 45 | C23: €/hour | D23: Average freelance rate (€35-55 range)
A24: Product Designer Hourly Rate | B24: 40 | C24: €/hour | D24: Average freelance rate (€30-50 range)
A25: Hours per Day | B25: 8 | C25: hours | D25: Standard working day
A27: Engineer Daily Cost | B27: =B22*$B$25 -> 320 | C27: €/day | D27: Calculated from hourly rate
A28: Product Manager Daily Cost | B28: =B23*$B$25 -> 360 | C28: €/day | D28: Calculated from hourly rate
A29: Product Designer Daily Cost | B29: =B24*$B$25 -> 320 | C29: €/day | D29: Calculated from hourly rate
A31: Operational Management
A32: BD/Account Manager Salary | B32: 85000 | C32: €/year | D32: Annual salary
A33: BD/Account Manager per X Teams | B33: 3 | C33: teams | D33: Number of teams one manager can oversee
A34: Benefits Multiplier | B34: 25% | C34: percentage | D34: Employer taxes & benefits
A36: ENTERPRISE REVENUE & COST MODEL (YEAR 1)
B38: Month 1 | C38: Month 2 | D38: Month 3 | E38: Month 4 | F38: Month 5 | G38: Month 6 | H38: Month 7 | I38: Month 8 | J38: Month 9 | K38: Month 10 | L38: Month 11 | M38: Month 12
B39: 45838 | C39: 45869 | D39: 45900 | E39: 45930 | F39: 45961 | G39: 45991 | H39: 46022 | I39: 46053 | J39: 46081 | K39: 46112 | L39: 46142 | M39: 46173
A41: Project Pipeline
A42: New Small Projects | B42: 0 | C42: 1 | D42: 0 | E42: 1 | F42: 0 | G42: 1 | H42: 0 | I42: 1 | J42: 0 | K42: 1 | L42: 0 | M42: 1 | N42: =SUM(B42:M42) -> 6
A43: New Medium Projects | B43: 0 | C43: 0 | D43: 1 | E43: 0 | F43: 0 | G43: 0 | H43: 1 | I43: 0 | J43: 0 | K43: 0 | L43: 1 | M43: 0 | N43: =SUM(B43:M43) -> 3
A45: Active Small Projects | B45: 0 | C45: =SUM(B42:C42) -> 1 | D45: =SUM(B42:D42) -> 1 | E45: =SUM(C42:E42) -> 2 | F45: =SUM(D42:F42) -> 1 | G45: =SUM(E42:G42) -> 2 | H45: =SUM(F42:H42) -> 1 | I45: =SUM(G42:I42) -> 2 | J45: =SUM(H42:J42) -> 1 | K45: =SUM(I42:K42) -> 2 | ... M45: =SUM(K42:M42) -> 2
A46: Active Medium Projects | B46: 0 | C46: 0 | D46: =SUM(B43:D43) -> 1 | E46: =SUM(C43:E43) -> 1 | F46: =SUM(B43:F43) -> 1 | G46: =SUM(C43:G43) -> 1 | H46: =SUM(D43:H43) -> 2 | I46: =SUM(E43:I43) -> 1 | J46: =SUM(F43:J43) -> 1 | K46: =SUM(G43:K43) -> 1 | L46: =SUM(H43:L43) -> 2 | M46: =SUM(I43:M43) -> 1
A47: Total Active Projects | B47: =SUM(B45:B46) -> 0 | C47: =SUM(C45:C46) -> 1 | D47: =SUM(D45:D46) -> 2 | E47: =SUM(E45:E46) -> 3 | F47: =SUM(F45:F46) -> 2 | G47: =SUM(G45:G46) -> 3 | H47: =SUM(H45:H46) -> 3 | I47: =SUM(I45:I46) -> 3 | ... M47: =SUM(M45:M46) -> 3
A49: Contractors per Project Type
A50: Small Team - Total Members | B50: 0 | C50: 3 | D50: 3 | E50: 3 | F50: 3 | G50: 3 | H50: 3 | I50: 3 | J50: 3 | K50: 3 | L50: 3 | M50: 3
A51: Medium Team - Total Members | B51: 0 | C51: 0 | D51: 5 | E51: 5 | F51: 5 | G51: 5 | H51: 5 | I51: 5 | J51: 5 | K51: 5 | L51: 5 | M51: 5
...

Sheet SaaS - Model
A1: Month | B1: Repository Visitors | C1: Revenue | D1: New trial users | E1: New Paid Tier 1 Users | F1: New Paid Tier 2 Users | G1: Total Paid Tier 1 Users | H1: Total Paid Tier 2 Users | I1: Staff_Costs | J1: Fixed_OPEX | K1: Total_Costs | L1: SaaS EBITDA
A2: 2025-06-30 | B2: 50000 | C2: =G2 * (Assumptions!$B$4 * Assumptions!$B$19 + Assumptions!$B$5 / 12 * Assumptions!$B$20) + H2 * (Assumptions!$B$6 * Assumptions!$B$19 + Assumptions!$B$7 / 12 * Assumptions!$B$20) -> 5426.6667 | D2: =B2 * (Assumptions!$B$14) -> 250 | E2: =D2 * (Assumptions!$B$15) -> 50 | F2: =D2 * (Assumptions!$B$16) -> 12.5 | G2: =E2 -> 50 | H2: =F2 -> 12.5 | I2: =IF(ROW()-1<=12, INDEX($B$52:$M$52, 1, ROW()-1), IF(ROW()-1<=24, INDEX($P$52:$AA$52, 1, ROW()-1-12), INDEX($AD$52:$AO$52, 1, ROW()-1-24))) -> 41145.833 | J2: =$B$61 -> 6500 | K2: =IF(ROW()-1<=12, INDEX($B$63:$M$63, 1, ROW()-1), IF(ROW()-1<=24, INDEX($P$63:$AA$63, 1, ROW()-1-12), INDEX($AD$63:$AO$63, 1, ROW()-1-24))) -> 47645.833 | L2: =C2-K2 -> -42219.167
A3: 2025-07-31 | B3: =B2 * (1 + Assumptions!$B$11) -> 57500 | C3: =G3 * (Assumptions!$B$4 * Assumptions!$B$19 + Assumptions!$B$5 / 12 * Assumptions!$B$20) + H3 * (Assumptions!$B$6 * Assumptions!$B$19 + Assumptions!$B$7 / 12 * Assumptions!$B$20) -> 11551.408 | D3: =B3 * (Assumptions!$B$14) -> 287.5 | E3: =D3 * (Assumptions!$B$15) -> 57.5 | F3: =D3 * (Assumptions!$B$16) -> 14.375 | G3: =G2 * (1 - Assumptions!$B$17) + E3 -> 106 | H3: =H2 * (1 - Assumptions!$B$18) + F3 -> 26.6875 | I3: =IF(ROW()-1<=12, INDEX($B$52:$M$52, 1, ROW()-1), IF(ROW()-1<=24, INDEX($P$52:$AA$52, 1, ROW()-1-12), INDEX($AD$52:$AO$52, 1, ROW()-1-24))) -> 41145.833 | J3: =$B$61 -> 6500 | K3: =IF(ROW()-1<=12, INDEX($B$63:$M$63, 1, ROW()-1), IF(ROW()-1<=24, INDEX($P$63:$AA$63, 1, ROW()-1-12), INDEX($AD$63:$AO$63, 1, ROW()-1-24))) -> 47645.833 | L3: =C3-K3 -> -36094.425
A4: 2025-08-31 | B4: =B3 * (1 + Assumptions!$B$11) -> 66125 | C4: =G4 * (Assumptions!$B$4 * Assumptions!$B$19 + Assumptions!$B$5 / 12 * Assumptions!$B$20) + H4 * (Assumptions!$B$6 * Assumptions!$B$19 + Assumptions!$B$7 / 12 * Assumptions!$B$20) -> 18481.711 | D4: =B4 * (Assumptions!$B$14) -> 330.625 | E4: =D4 * (Assumptions!$B$15) -> 66.125 | F4: =D4 * (Assumptions!$B$16) -> 16.53125 | G4: =G3 * (1 - Assumptions!$B$17) + E4 -> 168.945 | H4: =H3 * (1 - Assumptions!$B$18) + F4 -> 42.818438 | I4: =IF(ROW()-1<=12, INDEX($B$52:$M$52, 1, ROW()-1), IF(ROW()-1<=24, INDEX($P$52:$AA$52, 1, ROW()-1-12), INDEX($AD$52:$AO$52, 1, ROW()-1-24))) -> 41145.833 | J4: =$B$61 -> 6500 | K4: =IF(ROW()-1<=12, INDEX($B$63:$M$63, 1, ROW()-1), IF(ROW()-1<=24, INDEX($P$63:$AA$63, 1, ROW()-1-12), INDEX($AD$63:$AO$63, 1, ROW()-1-24))) -> 47645.833 | L4: =C4-K4 -> -29164.122
A5: 2025-09-30 | B5: =B4 * (1 + Assumptions!$B$11) -> 76043.75 | C5: =G5 * (Assumptions!$B$4 * Assumptions!$B$19 + Assumptions!$B$5 / 12 * Assumptions!$B$20) + H5 * (Assumptions!$B$6 * Assumptions!$B$19 + Assumptions!$B$7 / 12 * Assumptions!$B$20) -> 26341.11 | D5: =B5 * (Assumptions!$B$14) -> 380.21875 | E5: =D5 * (Assumptions!$B$15) -> 76.04375 | F5: =D5 * (Assumptions!$B$16) -> 19.010938 | G5: =G4 * (1 - Assumptions!$B$17) + E5 -> 239.9204 | H5: =H4 * (1 - Assumptions!$B$18) + F5 -> 61.187098 | I5: =IF(ROW()-1<=12, INDEX($B$52:$M$52, 1, ROW()-1), IF(ROW()-1<=24, INDEX($P$52:$AA$52, 1, ROW()-1-12), INDEX($AD$52:$AO$52, 1, ROW()-1-24))) -> 41145.833 | J5: =$B$61 -> 6500 | K5: =IF(ROW()-1<=12, INDEX($B$63:$M$63, 1, ROW()-1), IF(ROW()-1<=24, INDEX($P$63:$AA$63, 1, ROW()-1-12), INDEX($AD$63:$AO$63, 1, ROW()-1-24))) -> 47645.833 | L5: =C5-K5 -> -21304.723
A6: 2025-10-31 | B6: =B5 * (1 + Assumptions!$B$11) -> 87450.312 | C6: =G6 * (Assumptions!$B$4 * Assumptions!$B$19 + Assumptions!$B$5 / 12 * Assumptions!$B$20) + H6 * (Assumptions!$B$6 * Assumptions!$B$19 + Assumptions!$B$7 / 12 * Assumptions!$B$20) -> 35271.603 | D6: =B6 * (Assumptions!$B$14) -> 437.25156 | E6: =D6 * (Assumptions!$B$15) -> 87.450312 | F6: =D6 * (Assumptions!$B$16) -> 21.862578 | G6: =G5 * (1 - Assumptions!$B$17) + E6 -> 320.1731 | H6: =H5 * (1 - Assumptions!$B$18) + F6 -> 82.13187 | I6: =IF(ROW()-1<=12, INDEX($B$52:$M$52, 1, ROW()-1), IF(ROW()-1<=24, INDEX($P$52:$AA$52, 1, ROW()-1-12), INDEX($AD$52:$AO$52, 1, ROW()-1-24))) -> 41145.833 | J6: =$B$61 -> 6500 | K6: =IF(ROW()-1<=12, INDEX($B$63:$M$63, 1, ROW()-1), IF(ROW()-1<=24, INDEX($P$63:$AA$63, 1, ROW()-1-12), INDEX($AD$63:$AO$63, 1, ROW()-1-24))) -> 47645.833 | L6: =C6-K6 -> -12374.231
A7: 2025-11-30 | B7: =B6 * (1 + Assumptions!$B$11) -> 100567.86 | C7: =G7 * (Assumptions!$B$4 * Assumptions!$B$19 + Assumptions!$B$5 / 12 * Assumptions!$B$20) + H7 * (Assumptions!$B$6 * Assumptions!$B$19 + Assumptions!$B$7 / 12 * Assumptions!$B$20) -> 45436.414 | D7: =B7 * (Assumptions!$B$14) -> 502.8393 | E7: =D7 * (Assumptions!$B$15) -> 100.56786 | F7: =D7 * (Assumptions!$B$16) -> 25.141965 | G7: =G6 * (1 - Assumptions!$B$17) + E7 -> 411.13577 | H7: =H6 * (1 - Assumptions!$B$18) + F7 -> 106.04186 | I7: =IF(ROW()-1<=12, INDEX($B$52:$M$52, 1, ROW()-1), IF(ROW()-1<=24, INDEX($P$52:$AA$52, 1, ROW()-1-12), INDEX($AD$52:$AO$52, 1, ROW()-1-24))) -> 41145.833 | J7: =$B$61 -> 6500 | K7: =IF(ROW()-1<=12, INDEX($B$63:$M$63, 1, ROW()-1), IF(ROW()-1<=24, INDEX($P$63:$AA$63, 1, ROW()-1-12), INDEX($AD$63:$AO$63, 1, ROW()-1-24))) -> 47645.833 | L7: =C7-K7 -> -2209.4193
A8: 2025-12-31 | B8: =B7 * (1 + Assumptions!$B$11) -> 115653.04 | C8: =G8 * (Assumptions!$B$4 * Assumptions!$B$19 + Assumptions!$B$5 / 12 * Assumptions!$B$20) + H8 * (Assumptions!$B$6 * Assumptions!$B$19 + Assumptions!$B$7 / 12 * Assumptions!$B$20) -> 57023.188 | D8: =B8 * (Assumptions!$B$14) -> 578.26519 | E8: =D8 * (Assumptions!$B$15) -> 115.65304 | F8: =D8 * (Assumptions!$B$16) -> 28.91326 | G8: =G7 * (1 - Assumptions!$B$17) + E8 -> 514.45473 | H8: =H7 * (1 - Assumptions!$B$18) + F8 -> 133.36449 | I8: =IF(ROW()-1<=12, INDEX($B$52:$M$52, 1, ROW()-1), IF(ROW()-1<=24, INDEX($P$52:$AA$52, 1, ROW()-1-12), INDEX($AD$52:$AO$52, 1, ROW()-1-24))) -> 41145.833 | J8: =$B$61 -> 6500 | K8: =IF(ROW()-1<=12, INDEX($B$63:$M$63, 1, ROW()-1), IF(ROW()-1<=24, INDEX($P$63:$AA$63, 1, ROW()-1-12), INDEX($AD$63:$AO$63, 1, ROW()-1-24))) -> 47645.833 | L8: =C8-K8 -> 9377.355
A9: 2026-01-31 | B9: =B8 * (1 + Assumptions!$B$11) -> 133000.99 | C9: =G9 * (Assumptions!$B$4 * Assumptions!$B$19 + Assumptions!$B$5 / 12 * Assumptions!$B$20) + H9 * (Assumptions!$B$6 * Assumptions!$B$19 + Assumptions!$B$7 / 12 * Assumptions!$B$20) -> 70247.651 | D9: =B9 * (Assumptions!$B$14) -> 665.00497 | E9: =D9 * (Assumptions!$B$15) -> 133.00099 | F9: =D9 * (Assumptions!$B$16) -> 33.250249 | G9: =G8 * (1 - Assumptions!$B$17) + E9 -> 632.02208 | H9: =H8 * (1 - Assumptions!$B$18) + F9 -> 164.61427 | I9: =IF(ROW()-1<=12, INDEX($B$52:$M$52, 1, ROW()-1), IF(ROW()-1<=24, INDEX($P$52:$AA$52, 1, ROW()-1-12), INDEX($AD$52:$AO$52, 1, ROW()-1-24))) -> 41145.833 | J9: =$B$61 -> 6500 | K9: =IF(ROW()-1<=12, INDEX($B$63:$M$63, 1, ROW()-1), IF(ROW()-1<=24, INDEX($P$63:$AA$63, 1, ROW()-1-12), INDEX($AD$63:$AO$63, 1, ROW()-1-24))) -> 47645.833 | L9: =C9-K9 -> 22601.817
A10: 2026-02-28 | B10: =B9 * (1 + Assumptions!$B$11) -> 152951.14 | C10: =G10 * (Assumptions!$B$4 * Assumptions!$B$19 + Assumptions!$B$5 / 12 * Assumptions!$B$20) + H10 * (Assumptions!$B$6 * Assumptions!$B$19 + Assumptions!$B$7 / 12 * Assumptions!$B$20) -> 85357.822 | D10: =B10 * (Assumptions!$B$14) -> 764.75572 | E10: =D10 * (Assumptions!$B$15) -> 152.95114 | F10: =D10 * (Assumptions!$B$16) -> 38.237786 | G10: =G9 * (1 - Assumptions!$B$17) + E10 -> 766.01256 | H10: =H9 * (1 - Assumptions!$B$18) + F10 -> 200.38284 | I10: =IF(ROW()-1<=12, INDEX($B$52:$M$52, 1, ROW()-1), IF(ROW()-1<=24, INDEX($P$52:$AA$52, 1, ROW()-1-12), INDEX($AD$52:$AO$52, 1, ROW()-1-24))) -> 41145.833 | J10: =$B$61 -> 6500 | K10: =IF(ROW()-1<=12, INDEX($B$63:$M$63, 1, ROW()-1), IF(ROW()-1<=24, INDEX($P$63:$AA$63, 1, ROW()-1-12), INDEX($AD$63:$AO$63, 1, ROW()-1-24))) -> 47645.833 | L10: =C10-K10 -> 37711.989
A11: 2026-03-31 | B11: =B10 * (1 + Assumptions!$B$11) -> 175893.81 | C11: =G11 * (Assumptions!$B$4 * Assumptions!$B$19 + Assumptions!$B$5 / 12 * Assumptions!$B$20) + H11 * (Assumptions!$B$6 * Assumptions!$B$19 + Assumptions!$B$7 / 12 * Assumptions!$B$20) -> 102638.87 | D11: =B11 * (Assumptions!$B$14) -> 879.46907 | E11: =D11 * (Assumptions!$B$15) -> 175.89381 | F11: =D11 * (Assumptions!$B$16) -> 43.973454 | G11: =G10 * (1 - Assumptions!$B$17) + E11 -> 918.926 | H11: =H10 * (1 - Assumptions!$B$18) + F11 -> 241.35055 | I11: =IF(ROW()-1<=12, INDEX($B$52:$M$52, 1, ROW()-1), IF(ROW()-1<=24, INDEX($P$52:$AA$52, 1, ROW()-1-12), INDEX($AD$52:$AO$52, 1, ROW()-1-24))) -> 41145.833 | J11: =$B$61 -> 6500 | K11: =IF(ROW()-1<=12, INDEX($B$63:$M$63, 1, ROW()-1), IF(ROW()-1<=24, INDEX($P$63:$AA$63, 1, ROW()-1-12), INDEX($AD$63:$AO$63, 1, ROW()-1-24))) -> 47645.833 | L11: =C11-K11 -> 54993.032
A12: 2026-04-30 | B12: =B11 * (1 + Assumptions!$B$11) -> 202277.89 | C12: =G12 * (Assumptions!$B$4 * Assumptions!$B$19 + Assumptions!$B$5 / 12 * Assumptions!$B$20) + H12 * (Assumptions!$B$6 * Assumptions!$B$19 + Assumptions!$B$7 / 12 * Assumptions!$B$20) -> 122418.66 | D12: =B12 * (Assumptions!$B$14) -> 1011.3894 | E12: =D12 * (Assumptions!$B$15) -> 202.27789 | F12: =D12 * (Assumptions!$B$16) -> 50.569472 | G12: =G11 * (1 - Assumptions!$B$17) + E12 -> 1093.6361 | H12: =H11 * (1 - Assumptions!$B$18) + F12 -> 288.29977 | I12: =IF(ROW()-1<=12, INDEX($B$52:$M$52, 1, ROW()-1), IF(ROW()-1<=24, INDEX($P$52:$AA$52, 1, ROW()-1-12), INDEX($AD$52:$AO$52, 1, ROW()-1-24))) -> 41145.833 | J12: =$B$61 -> 6500 | K12: =IF(ROW()-1<=12, INDEX($B$63:$M$63, 1, ROW()-1), IF(ROW()-1<=24, INDEX($P$63:$AA$63, 1, ROW()-1-12), INDEX($AD$63:$AO$63, 1, ROW()-1-24))) -> 47645.833 | L12: =C12-K12 -> 74772.824
A13: 2026-05-31 | B13: =B12 * (1 + Assumptions!$B$11) -> 232619.57 | C13: =G13 * (Assumptions!$B$4 * Assumptions!$B$19 + Assumptions!$B$5 / 12 * Assumptions!$B$20) + H13 * (Assumptions!$B$6 * Assumptions!$B$19 + Assumptions!$B$7 / 12 * Assumptions!$B$20) -> 145074.2 | D13: =B13 * (Assumptions!$B$14) -> 1163.0978 | E13: =D13 * (Assumptions!$B$15) -> 232.61957 | F13: =D13 * (Assumptions!$B$16) -> 58.154892 | G13: =G12 * (1 - Assumptions!$B$17) + E13 -> 1293.4466 | H13: =H12 * (1 - Assumptions!$B$18) + F13 -> 342.13016 | I13: =IF(ROW()-1<=12, INDEX($B$52:$M$52, 1, ROW()-1), IF(ROW()-1<=24, INDEX($P$52:$AA$52, 1, ROW()-1-12), INDEX($AD$52:$AO$52, 1, ROW()-1-24))) -> 41145.833 | J13: =$B$61 -> 6500 | K13: =IF(ROW()-1<=12, INDEX($B$63:$M$63, 1, ROW()-1), IF(ROW()-1<=24, INDEX($P$63:$AA$63, 1, ROW()-1-12), INDEX($AD$63:$AO$63, 1, ROW()-1-24))) -> 47645.833 | L13: =C13-K13 -> 97428.365
A14: 2026-06-30 | B14: =B13 * (1 + Assumptions!$B$12) -> 255881.53 | C14: =G14 * (Assumptions!$B$4 * Assumptions!$B$19 + Assumptions!$B$5 / 12 * Assumptions!$B$20) + H14 * (Assumptions!$B$6 * Assumptions!$B$19 + Assumptions!$B$7 / 12 * Assumptions!$B$20) -> 169776.64 | D14: =B14 * (Assumptions!$B$14) -> 1279.4076 | E14: =D14 * (Assumptions!$B$15) -> 255.88153 | F14: =D14 * (Assumptions!$B$16) -> 63.970382 | G14: =G13 * (1 - Assumptions!$B$17) + E14 -> 1510.5247 | H14: =H13 * (1 - Assumptions!$B$18) + F14 -> 400.96859 | I14: =IF(ROW()-1<=12, INDEX($B$52:$M$52, 1, ROW()-1), IF(ROW()-1<=24, INDEX($P$52:$AA$52, 1, ROW()-1-12), INDEX($AD$52:$AO$52, 1, ROW()-1-24))) -> 73958.333 | J14: =$B$61 -> 6500 | K14: =IF(ROW()-1<=12, INDEX($B$63:$M$63, 1, ROW()-1), IF(ROW()-1<=24, INDEX($P$63:$AA$63, 1, ROW()-1-12), INDEX($AD$63:$AO$63, 1, ROW()-1-24))) -> 85658.333 | L14: =C14-K14 -> 84118.303
A15: 2026-07-31 | B15: =B14 * (1 + Assumptions!$B$12) -> 281469.68 | C15: =G15 * (Assumptions!$B$4 * Assumptions!$B$19 + Assumptions!$B$5 / 12 * Assumptions!$B$20) + H15 * (Assumptions!$B$6 * Assumptions!$B$19 + Assumptions!$B$7 / 12 * Assumptions!$B$20) -> 196735.81 | D15: =B15 * (Assumptions!$B$14) -> 1407.3484 | E15: =D15 * (Assumptions!$B$15) -> 281.46968 | F15: =D15 * (Assumptions!$B$16) -> 70.36742 | G15: =G14 * (1 - Assumptions!$B$17) + E15 -> 1746.6787 | H15: =H14 * (1 - Assumptions!$B$18) + F15 -> 465.32148 | I15: =IF(ROW()-1<=12, INDEX($B$52:$M$52, 1, ROW()-1), IF(ROW()-1<=24, INDEX($P$52:$AA$52, 1, ROW()-1-12), INDEX($AD$52:$AO$52, 1, ROW()-1-24))) -> 73958.333 | J15: =$P$61 -> 11700 | K15: =IF(ROW()-1<=12, INDEX($B$63:$M$63, 1, ROW()-1), IF(ROW()-1<=24, INDEX($P$63:$AA$63, 1, ROW()-1-12), INDEX($AD$63:$AO$63, 1, ROW()-1-24))) -> 85658.333 | L15: =C15-K15 -> 111077.48
A16: 2026-08-31 | B16: =B15 * (1 + Assumptions!$B$12) -> 309616.65 | C16: =G16 * (Assumptions!$B$4 * Assumptions!$B$19 + Assumptions!$B$5 / 12 * Assumptions!$B$20) + H16 * (Assumptions!$B$6 * Assumptions!$B$19 + Assumptions!$B$7 / 12 * Assumptions!$B$20) -> 226182.42 | D16: =B16 * (Assumptions!$B$14) -> 1548.0832 | E16: =D16 * (Assumptions!$B$15) -> 309.61665 | F16: =D16 * (Assumptions!$B$16) -> 77.404162 | G16: =G15 * (1 - Assumptions!$B$17) + E16 -> 2003.895 | H16: =H15 * (1 - Assumptions!$B$18) + F16 -> 535.74582 | I16: =IF(ROW()-1<=12, INDEX($B$52:$M$52, 1, ROW()-1), IF(ROW()-1<=24, INDEX($P$52:$AA$52, 1, ROW()-1-12), INDEX($AD$52:$AO$52, 1, ROW()-1-24))) -> 73958.333 | J16: =$P$61 -> 11700 | K16: =IF(ROW()-1<=12, INDEX($B$63:$M$63, 1, ROW()-1), IF(ROW()-1<=24, INDEX($P$63:$AA$63, 1, ROW()-1-12), INDEX($AD$63:$AO$63, 1, ROW()-1-24))) -> 85658.333 | L16: =C16-K16 -> 140524.09
A17: 2026-09-30 | B17: =B16 * (1 + Assumptions!$B$12) -> 340578.31 | C17: =G17 * (Assumptions!$B$4 * Assumptions!$B$19 + Assumptions!$B$5 / 12 * Assumptions!$B$20) + H17 * (Assumptions!$B$6 * Assumptions!$B$19 + Assumptions!$B$7 / 12 * Assumptions!$B$20) -> 258370.09 | D17: =B17 * (Assumptions!$B$14) -> 1702.8916 | E17: =D17 * (Assumptions!$B$15) -> 340.57831 | F17: =D17 * (Assumptions!$B$16) -> 85.144578 | G17: =G16 * (1 - Assumptions!$B$17) + E17 -> 2284.3564 | H17: =H16 * (1 - Assumptions!$B$18) + F17 -> 612.85421 | I17: =IF(ROW()-1<=12, INDEX($B$52:$M$52, 1, ROW()-1), IF(ROW()-1<=24, INDEX($P$52:$AA$52, 1, ROW()-1-12), INDEX($AD$52:$AO$52, 1, ROW()-1-24))) -> 73958.333 | J17: =$P$61 -> 11700 | K17: =IF(ROW()-1<=12, INDEX($B$63:$M$63, 1, ROW()-1), IF(ROW()-1<=24, INDEX($P$63:$AA$63, 1, ROW()-1-12), INDEX($AD$63:$AO$63, 1, ROW()-1-24))) -> 85658.333 | L17: =C17-K17 -> 172711.76
A18: 2026-10-31 | B18: =B17 * (1 + Assumptions!$B$12) -> 374636.14 | C18: =G18 * (Assumptions!$B$4 * Assumptions!$B$19 + Assumptions!$B$5 / 12 * Assumptions!$B$20) + H18 * (Assumptions!$B$6 * Assumptions!$B$19 + Assumptions!$B$7 / 12 * Assumptions!$B$20) -> 293577.7 | D18: =B18 * (Assumptions!$B$14) -> 1873.1807 | E18: =D18 * (Assumptions!$B$15) -> 374.63614 | F18: =D18 * (Assumptions!$B$16) -> 93.659036 | G18: =G17 * (1 - Assumptions!$B$17) + E18 -> 2590.4619 | H18: =H17 * (1 - Assumptions!$B$18) + F18 -> 697.32044 | I18: =IF(ROW()-1<=12, INDEX($B$52:$M$52, 1, ROW()-1), IF(ROW()-1<=24, INDEX($P$52:$AA$52, 1, ROW()-1-12), INDEX($AD$52:$AO$52, 1, ROW()-1-24))) -> 73958.333 | J18: =$P$61 -> 11700 | K18: =IF(ROW()-1<=12, INDEX($B$63:$M$63, 1, ROW()-1), IF(ROW()-1<=24, INDEX($P$63:$AA$63, 1, ROW()-1-12), INDEX($AD$63:$AO$63, 1, ROW()-1-24))) -> 85658.333 | L18: =C18-K18 -> 207919.37
A19: 2026-11-30 | B19: =B18 * (1 + Assumptions!$B$12) -> 412099.76 | C19: =G19 * (Assumptions!$B$4 * Assumptions!$B$19 + Assumptions!$B$5 / 12 * Assumptions!$B$20) + H19 * (Assumptions!$B$6 * Assumptions!$B$19 + Assumptions!$B$7 / 12 * Assumptions!$B$20) -> 332111.88 | D19: =B19 * (Assumptions!$B$14) -> 2060.4988 | E19: =D19 * (Assumptions!$B$15) -> 412.09976 | F19: =D19 * (Assumptions!$B$16) -> 103.02494 | G19: =G18 * (1 - Assumptions!$B$17) + E19 -> 2924.8478 | H19: =H18 * (1 - Assumptions!$B$18) + F19 -> 789.88557 | I19: =IF(ROW()-1<=12, INDEX($B$52:$M$52, 1, ROW()-1), IF(ROW()-1<=24, INDEX($P$52:$AA$52, 1, ROW()-1-12), INDEX($AD$52:$AO$52, 1, ROW()-1-24))) -> 73958.333 | J19: =$P$61 -> 11700 | K19: =IF(ROW()-1<=12, INDEX($B$63:$M$63, 1, ROW()-1), IF(ROW()-1<=24, INDEX($P$63:$AA$63, 1, ROW()-1-12), INDEX($AD$63:$AO$63, 1, ROW()-1-24))) -> 85658.333 | L19: =C19-K19 -> 246453.55
A20: 2026-12-31 | B20: =B19 * (1 + Assumptions!$B$12) -> 453309.73 | C20: =G20 * (Assumptions!$B$4 * Assumptions!$B$19 + Assumptions!$B$5 / 12 * Assumptions!$B$20) + H20 * (Assumptions!$B$6 * Assumptions!$B$19 + Assumptions!$B$7 / 12 * Assumptions!$B$20) -> 374309.81 | D20: =B20 * (Assumptions!$B$14) -> 2266.5487 | E20: =D20 * (Assumptions!$B$15) -> 453.30973 | F20: =D20 * (Assumptions!$B$16) -> 113.32743 | G20: =G19 * (1 - Assumptions!$B$17) + E20 -> 3290.4121 | H20: =H19 * (1 - Assumptions!$B$18) + F20 -> 891.36472 | I20: =IF(ROW()-1<=12, INDEX($B$52:$M$52, 1, ROW()-1), IF(ROW()-1<=24, INDEX($P$52:$AA$52, 1, ROW()-1-12), INDEX($AD$52:$AO$52, 1, ROW()-1-24))) -> 73958.333 | J20: =$P$61 -> 11700 | K20: =IF(ROW()-1<=12, INDEX($B$63:$M$63, 1, ROW()-1), IF(ROW()-1<=24, INDEX($P$63:$AA$63, 1, ROW()-1-12), INDEX($AD$63:$AO$63, 1, ROW()-1-24))) -> 85658.333 | L20: =C20-K20 -> 288651.48
A21: 2027-01-31 | B21: =B20 * (1 + Assumptions!$B$12) -> 498640.71 | C21: =G21 * (Assumptions!$B$4 * Assumptions!$B$19 + Assumptions!$B$5 / 12 * Assumptions!$B$20) + H21 * (Assumptions!$B$6 * Assumptions!$B$19 + Assumptions!$B$7 / 12 * Assumptions!$B$20) -> 420542.28 | D21: =B21 * (Assumptions!$B$14) -> 2493.2035 | E21: =D21 * (Assumptions!$B$15) -> 498.64071 | F21: =D21 * (Assumptions!$B$16) -> 124.66018 | G21: =G20 * (1 - Assumptions!$B$17) + E21 -> 3690.3404 | H21: =H20 * (1 - Assumptions!$B$18) + F21 -> 1002.6544 | I21: =IF(ROW()-1<=12, INDEX($B$52:$M$52, 1, ROW()-1), IF(ROW()-1<=24, INDEX($P$52:$AA$52, 1, ROW()-1-12), INDEX($AD$52:$AO$52, 1, ROW()-1-24))) -> 73958.333 | J21: =$P$61 -> 11700 | K21: =IF(ROW()-1<=12, INDEX($B$63:$M$63, 1, ROW()-1), IF(ROW()-1<=24, INDEX($P$63:$AA$63, 1, ROW()-1-12), INDEX($AD$63:$AO$63, 1, ROW()-1-24))) -> 85658.333 | L21: =C21-K21 -> 334883.94
A22: 2027-02-28 | B22: =B21 * (1 + Assumptions!$B$12) -> 548504.78 | C22: =G22 * (Assumptions!$B$4 * Assumptions!$B$19 + Assumptions!$B$5 / 12 * Assumptions!$B$20) + H22 * (Assumptions!$B$6 * Assumptions!$B$19 + Assumptions!$B$7 / 12 * Assumptions!$B$20) -> 471217.01 | D22: =B22 * (Assumptions!$B$14) -> 2742.5239 | E22: =D22 * (Assumptions!$B$15) -> 548.50478 | F22: =D22 * (Assumptions!$B$16) -> 137.12619 | G22: =G21 * (1 - Assumptions!$B$17) + E22 -> 4128.135 | H22: =H21 * (1 - Assumptions!$B$18) + F22 -> 1124.7408 | I22: =IF(ROW()-1<=12, INDEX($B$52:$M$52, 1, ROW()-1), IF(ROW()-1<=24, INDEX($P$52:$AA$52, 1, ROW()-1-12), INDEX($AD$52:$AO$52, 1, ROW()-1-24))) -> 73958.333 | J22: =$P$61 -> 11700 | K22: =IF(ROW()-1<=12, INDEX($B$63:$M$63, 1, ROW()-1), IF(ROW()-1<=24, INDEX($P$63:$AA$63, 1, ROW()-1-12), INDEX($AD$63:$AO$63, 1, ROW()-1-24))) -> 85658.333 | L22: =C22-K22 -> 385558.68
A23: 2027-03-31 | B23: =B22 * (1 + Assumptions!$B$12) -> 603355.26 | C23: =G23 * (Assumptions!$B$4 * Assumptions!$B$19 + Assumptions!$B$5 / 12 * Assumptions!$B$20) + H23 * (Assumptions!$B$6 * Assumptions!$B$19 + Assumptions!$B$7 / 12 * Assumptions!$B$20) -> 526782.44 | D23: =B23 * (Assumptions!$B$14) -> 3016.7763 | E23: =D23 * (Assumptions!$B$15) -> 603.35526 | F23: =D23 * (Assumptions!$B$16) -> 150.83881 | G23: =G22 * (1 - Assumptions!$B$17) + E23 -> 4607.6462 | H23: =H22 * (1 - Assumptions!$B$18) + F23 -> 1258.7085 | I23: =IF(ROW()-1<=12, INDEX($B$52:$M$52, 1, ROW()-1), IF(ROW()-1<=24, INDEX($P$52:$AA$52, 1, ROW()-1-12), INDEX($AD$52:$AO$52, 1, ROW()-1-24))) -> 73958.333 | J23: =$P$61 -> 11700 | K23: =IF(ROW()-1<=12, INDEX($B$63:$M$63, 1, ROW()-1), IF(ROW()-1<=24, INDEX($P$63:$AA$63, 1, ROW()-1-12), INDEX($AD$63:$AO$63, 1, ROW()-1-24))) -> 85658.333 | L23: =C23-K23 -> 441124.11
A24: 2027-04-30 | B24: =B23 * (1 + Assumptions!$B$12) -> 663690.78 | C24: =G24 * (Assumptions!$B$4 * Assumptions!$B$19 + Assumptions!$B$5 / 12 * Assumptions!$B$20) + H24 * (Assumptions!$B$6 * Assumptions!$B$19 + Assumptions!$B$7 / 12 * Assumptions!$B$20) -> 587731.69 | D24: =B24 * (Assumptions!$B$14) -> 3318.4539 | E24: =D24 * (Assumptions!$B$15) -> 663.69078 | F24: =D24 * (Assumptions!$B$16) -> 165.9227 | G24: =G23 * (1 - Assumptions!$B$17) + E24 -> 5133.1076 | H24: =H23 * (1 - Assumptions!$B$18) + F24 -> 1405.7506 | I24: =IF(ROW()-1<=12, INDEX($B$52:$M$52, 1, ROW()-1), IF(ROW()-1<=24, INDEX($P$52:$AA$52, 1, ROW()-1-12), INDEX($AD$52:$AO$52, 1, ROW()-1-24))) -> 73958.333 | J24: =$P$61 -> 11700 | K24: =IF(ROW()-1<=12, INDEX($B$63:$M$63, 1, ROW()-1), IF(ROW()-1<=24, INDEX($P$63:$AA$63, 1, ROW()-1-12), INDEX($AD$63:$AO$63, 1, ROW()-1-24))) -> 85658.333 | L24: =C24-K24 -> 502073.36
A25: 2027-05-31 | B25: =B24 * (1 + Assumptions!$B$12) -> 730059.86 | C25: =G25 * (Assumptions!$B$4 * Assumptions!$B$19 + Assumptions!$B$5 / 12 * Assumptions!$B$20) + H25 * (Assumptions!$B$6 * Assumptions!$B$19 + Assumptions!$B$7 / 12 * Assumptions!$B$20) -> 654607.14 | D25: =B25 * (Assumptions!$B$14) -> 3650.2993 | E25: =D25 * (Assumptions!$B$15) -> 730.05986 | F25: =D25 * (Assumptions!$B$16) -> 182.51496 | G25: =G24 * (1 - Assumptions!$B$17) + E25 -> 5709.1742 | H25: =H24 * (1 - Assumptions!$B$18) + F25 -> 1567.1793 | I25: =IF(ROW()-1<=12, INDEX($B$52:$M$52, 1, ROW()-1), IF(ROW()-1<=24, INDEX($P$52:$AA$52, 1, ROW()-1-12), INDEX($AD$52:$AO$52, 1, ROW()-1-24))) -> 73958.333 | J25: =$P$61 -> 11700 | K25: =IF(ROW()-1<=12, INDEX($B$63:$M$63, 1, ROW()-1), IF(ROW()-1<=24, INDEX($P$63:$AA$63, 1, ROW()-1-12), INDEX($AD$63:$AO$63, 1, ROW()-1-24))) -> 85658.333 | L25: =C25-K25 -> 568948.81
A26: 2027-06-30 | B26: =B25 * (1 + Assumptions!$B$12) -> 803065.84 | C26: =G26 * (Assumptions!$B$4 * Assumptions!$B$19 + Assumptions!$B$5 / 12 * Assumptions!$B$20) + H26 * (Assumptions!$B$6 * Assumptions!$B$19 + Assumptions!$B$7 / 12 * Assumptions!$B$20) -> 728005.26 | D26: =B26 * (Assumptions!$B$14) -> 4015.3292 | E26: =D26 * (Assumptions!$B$15) -> 803.06584 | F26: =D26 * (Assumptions!$B$16) -> 200.76646 | G26: =G25 * (1 - Assumptions!$B$17) + E26 -> 6340.9648 | H26: =H25 * (1 - Assumptions!$B$18) + F26 -> 1744.438 | I26: =IF(ROW()-1<=12, INDEX($B$52:$M$52, 1, ROW()-1), IF(ROW()-1<=24, INDEX($P$52:$AA$52, 1, ROW()-1-12), INDEX($AD$52:$AO$52, 1, ROW()-1-24))) -> 115104.17 | J26: =$P$61 -> 11700 | K26: =IF(ROW()-1<=12, INDEX($B$63:$M$63, 1, ROW()-1), IF(ROW()-1<=24, INDEX($P$63:$AA$63, 1, ROW()-1-12), INDEX($AD$63:$AO$63, 1, ROW()-1-24))) -> 133304.17 | L26: =C26-K26 -> 594701.09
A27: 2027-07-31 | B27: =B26 * (1 + Assumptions!$B$13) -> 859280.45 | C27: =G27 * (Assumptions!$B$4 * Assumptions!$B$19 + Assumptions!$B$5 / 12 * Assumptions!$B$20) + H27 * (Assumptions!$B$6 * Assumptions!$B$19 + Assumptions!$B$7 / 12 * Assumptions!$B$20) -> 805967.32 | D27: =B27 * (Assumptions!$B$14) -> 4296.4023 | E27: =D27 * (Assumptions!$B$15) -> 859.28045 | F27: =D27 * (Assumptions!$B$16) -> 214.82011 | G27: =G26 * (1 - Assumptions!$B$17) + E27 -> 7010.0163 | H27: =H26 * (1 - Assumptions!$B$18) + F27 -> 1933.0916 | I27: =IF(ROW()-1<=12, INDEX($B$52:$M$52, 1, ROW()-1), IF(ROW()-1<=24, INDEX($P$52:$AA$52, 1, ROW()-1-12), INDEX($AD$52:$AO$52, 1, ROW()-1-24))) -> 115104.17 | J27: =$AD$61 -> 18200 | K27: =IF(ROW()-1<=12, INDEX($B$63:$M$63, 1, ROW()-1), IF(ROW()-1<=24, INDEX($P$63:$AA$63, 1, ROW()-1-12), INDEX($AD$63:$AO$63, 1, ROW()-1-24))) -> 133304.17 | L27: =C27-K27 -> 672663.15
A28: 2027-08-31 | B28: =B27 * (1 + Assumptions!$B$13) -> 919430.09 | C28: =G28 * (Assumptions!$B$4 * Assumptions!$B$19 + Assumptions!$B$5 / 12 * Assumptions!$B$20) + H28 * (Assumptions!$B$6 * Assumptions!$B$19 + Assumptions!$B$7 / 12 * Assumptions!$B$20) -> 888826.2 | D28: =B28 * (Assumptions!$B$14) -> 4597.1504 | E28: =D28 * (Assumptions!$B$15) -> 919.43009 | F28: =D28 * (Assumptions!$B$16) -> 229.85752 | G28: =G27 * (1 - Assumptions!$B$17) + E28 -> 7719.1459 | H28: =H27 * (1 - Assumptions!$B$18) + F28 -> 2133.9527 | I28: =IF(ROW()-1<=12, INDEX($B$52:$M$52, 1, ROW()-1), IF(ROW()-1<=24, INDEX($P$52:$AA$52, 1, ROW()-1-12), INDEX($AD$52:$AO$52, 1, ROW()-1-24))) -> 115104.17 | J28: =$AD$61 -> 18200 | K28: =IF(ROW()-1<=12, INDEX($B$63:$M$63, 1, ROW()-1), IF(ROW()-1<=24, INDEX($P$63:$AA$63, 1, ROW()-1-12), INDEX($AD$63:$AO$63, 1, ROW()-1-24))) -> 133304.17 | L28: =C28-K28 -> 755522.04
A29: 2027-09-30 | B29: =B28 * (1 + Assumptions!$B$13) -> 983790.19 | C29: =G29 * (Assumptions!$B$4 * Assumptions!$B$19 + Assumptions!$B$5 / 12 * Assumptions!$B$20) + H29 * (Assumptions!$B$6 * Assumptions!$B$19 + Assumptions!$B$7 / 12 * Assumptions!$B$20) -> 976937.77 | D29: =B29 * (Assumptions!$B$14) -> 4918.951 | E29: =D29 * (Assumptions!$B$15) -> 983.79019 | F29: =D29 * (Assumptions!$B$16) -> 245.94755 | G29: =G28 * (1 - Assumptions!$B$17) + E29 -> 8471.3617 | H29: =H28 * (1 - Assumptions!$B$18) + F29 -> 2347.891 | I29: =IF(ROW()-1<=12, INDEX($B$52:$M$52, 1, ROW()-1), IF(ROW()-1<=24, INDEX($P$52:$AA$52, 1, ROW()-1-12), INDEX($AD$52:$AO$52, 1, ROW()-1-24))) -> 115104.17 | J29: =$AD$61 -> 18200 | K29: =IF(ROW()-1<=12, INDEX($B$63:$M$63, 1, ROW()-1), IF(ROW()-1<=24, INDEX($P$63:$AA$63, 1, ROW()-1-12), INDEX($AD$63:$AO$63, 1, ROW()-1-24))) -> 133304.17 | L29: =C29-K29 -> 843633.6
A30: 2027-10-31 | B30: =B29 * (1 + Assumptions!$B$13) -> 1052655.5 | C30: =G30 * (Assumptions!$B$4 * Assumptions!$B$19 + Assumptions!$B$5 / 12 * Assumptions!$B$20) + H30 * (Assumptions!$B$6 * Assumptions!$B$19 + Assumptions!$B$7 / 12 * Assumptions!$B$20) -> 1070682.4 | D30: =B30 * (Assumptions!$B$14) -> 5263.2775 | E30: =D30 * (Assumptions!$B$15) -> 1052.6555 | F30: =D30 * (Assumptions!$B$16) -> 263.16388 | G30: =G29 * (1 - Assumptions!$B$17) + E30 -> 9269.8764 | H30: =H29 * (1 - Assumptions!$B$18) + F30 -> 2575.8365 | I30: =IF(ROW()-1<=12, INDEX($B$52:$M$52, 1, ROW()-1), IF(ROW()-1<=24, INDEX($P$52:$AA$52, 1, ROW()-1-12), INDEX($AD$52:$AO$52, 1, ROW()-1-24))) -> 115104.17 | J30: =$AD$61 -> 18200 | K30: =IF(ROW()-1<=12, INDEX($B$63:$M$63, 1, ROW()-1), IF(ROW()-1<=24, INDEX($P$63:$AA$63, 1, ROW()-1-12), INDEX($AD$63:$AO$63, 1, ROW()-1-24))) -> 133304.17 | L30: =C30-K30 -> 937378.27
A31: 2027-11-30 | B31: =B30 * (1 + Assumptions!$B$13) -> 1126341.4 | C31: =G31 * (Assumptions!$B$4 * Assumptions!$B$19 + Assumptions!$B$5 / 12 * Assumptions!$B$20) + H31 * (Assumptions!$B$6 * Assumptions!$B$19 + Assumptions!$B$7 / 12 * Assumptions!$B$20) -> 1170466.9 | D31: =B31 * (Assumptions!$B$14) -> 5631.707 | E31: =D31 * (Assumptions!$B$15) -> 1126.3414 | F31: =D31 * (Assumptions!$B$16) -> 281.58535 | G31: =G30 * (1 - Assumptions!$B$17) + E31 -> 10118.121 | H31: =H30 * (1 - Assumptions!$B$18) + F31 -> 2818.7843 | I31: =IF(ROW()-1<=12, INDEX($B$52:$M$52, 1, ROW()-1), IF(ROW()-1<=24, INDEX($P$52:$AA$52, 1, ROW()-1-12), INDEX($AD$52:$AO$52, 1, ROW()-1-24))) -> 115104.17 | J31: =$AD$61 -> 18200 | K31: =IF(ROW()-1<=12, INDEX($B$63:$M$63, 1, ROW()-1), IF(ROW()-1<=24, INDEX($P$63:$AA$63, 1, ROW()-1-12), INDEX($AD$63:$AO$63, 1, ROW()-1-24))) -> 133304.17 | L31: =C31-K31 -> 1037162.8
A32: 2027-12-31 | B32: =B31 * (1 + Assumptions!$B$13) -> 1205185.3 | C32: =G32 * (Assumptions!$B$4 * Assumptions!$B$19 + Assumptions!$B$5 / 12 * Assumptions!$B$20) + H32 * (Assumptions!$B$6 * Assumptions!$B$19 + Assumptions!$B$7 / 12 * Assumptions!$B$20) -> 1276726.1 | D32: =B32 * (Assumptions!$B$14) -> 6025.9264 | E32: =D32 * (Assumptions!$B$15) -> 1205.1853 | F32: =D32 * (Assumptions!$B$16) -> 301.29632 | G32: =G31 * (1 - Assumptions!$B$17) + E32 -> 11019.763 | H32: =H31 * (1 - Assumptions!$B$18) + F32 -> 3077.7989 | I32: =IF(ROW()-1<=12, INDEX($B$52:$M$52, 1, ROW()-1), IF(ROW()-1<=24, INDEX($P$52:$AA$52, 1, ROW()-1-12), INDEX($AD$52:$AO$52, 1, ROW()-1-24))) -> 115104.17 | J32: =$AD$61 -> 18200 | K32: =IF(ROW()-1<=12, INDEX($B$63:$M$63, 1, ROW()-1), IF(ROW()-1<=24, INDEX($P$63:$AA$63, 1, ROW()-1-12), INDEX($AD$63:$AO$63, 1, ROW()-1-24))) -> 133304.17 | L32: =C32-K32 -> 1143422
A33: 2028-01-31 | B33: =B32 * (1 + Assumptions!$B$13) -> 1289548.3 | C33: =G33 * (Assumptions!$B$4 * Assumptions!$B$19 + Assumptions!$B$5 / 12 * Assumptions!$B$20) + H33 * (Assumptions!$B$6 * Assumptions!$B$19 + Assumptions!$B$7 / 12 * Assumptions!$B$20) -> 1389925.1 | D33: =B33 * (Assumptions!$B$14) -> 6447.7413 | E33: =D33 * (Assumptions!$B$15) -> 1289.5483 | F33: =D33 * (Assumptions!$B$16) -> 322.38706 | G33: =G32 * (1 - Assumptions!$B$17) + E33 -> 11978.719 | H33: =H32 * (1 - Assumptions!$B$18) + F33 -> 3354.0189 | I33: =IF(ROW()-1<=12, INDEX($B$52:$M$52, 1, ROW()-1), IF(ROW()-1<=24, INDEX($P$52:$AA$52, 1, ROW()-1-12), INDEX($AD$52:$AO$52, 1, ROW()-1-24))) -> 115104.17 | J33: =$AD$61 -> 18200 | K33: =IF(ROW()-1<=12, INDEX($B$63:$M$63, 1, ROW()-1), IF(ROW()-1<=24, INDEX($P$63:$AA$63, 1, ROW()-1-12), INDEX($AD$63:$AO$63, 1, ROW()-1-24))) -> 133304.17 | L33: =C33-K33 -> 1256620.9
A34: 2028-02-29 | B34: =B33 * (1 + Assumptions!$B$13) -> 1379816.6 | C34: =G34 * (Assumptions!$B$4 * Assumptions!$B$19 + Assumptions!$B$5 / 12 * Assumptions!$B$20) + H34 * (Assumptions!$B$6 * Assumptions!$B$19 + Assumptions!$B$7 / 12 * Assumptions!$B$20) -> 1510561 | D34: =B34 * (Assumptions!$B$14) -> 6899.0832 | E34: =D34 * (Assumptions!$B$15) -> 1379.8166 | F34: =D34 * (Assumptions!$B$16) -> 344.95416 | G34: =G33 * (1 - Assumptions!$B$17) + E34 -> 12999.174 | H34: =H33 * (1 - Assumptions!$B$18) + F34 -> 3648.6628 | I34: =IF(ROW()-1<=12, INDEX($B$52:$M$52, 1, ROW()-1), IF(ROW()-1<=24, INDEX($P$52:$AA$52, 1, ROW()-1-12), INDEX($AD$52:$AO$52, 1, ROW()-1-24))) -> 115104.17 | J34: =$AD$61 -> 18200 | K34: =IF(ROW()-1<=12, INDEX($B$63:$M$63, 1, ROW()-1), IF(ROW()-1<=24, INDEX($P$63:$AA$63, 1, ROW()-1-12), INDEX($AD$63:$AO$63, 1, ROW()-1-24))) -> 133304.17 | L34: =C34-K34 -> 1377256.8
A35: 2028-03-31 | B35: =B34 * (1 + Assumptions!$B$13) -> 1476403.8 | C35: =G35 * (Assumptions!$B$4 * Assumptions!$B$19 + Assumptions!$B$5 / 12 * Assumptions!$B$20) + H35 * (Assumptions!$B$6 * Assumptions!$B$19 + Assumptions!$B$7 / 12 * Assumptions!$B$20) -> 1639165.7 | D35: =B35 * (Assumptions!$B$14) -> 7382.019 | E35: =D35 * (Assumptions!$B$15) -> 1476.4038 | F35: =D35 * (Assumptions!$B$16) -> 369.10095 | G35: =G34 * (1 - Assumptions!$B$17) + E35 -> 14085.602 | H35: =H34 * (1 - Assumptions!$B$18) + F35 -> 3963.0338 | I35: =IF(ROW()-1<=12, INDEX($B$52:$M$52, 1, ROW()-1), IF(ROW()-1<=24, INDEX($P$52:$AA$52, 1, ROW()-1-12), INDEX($AD$52:$AO$52, 1, ROW()-1-24))) -> 115104.17 | J35: =$AD$61 -> 18200 | K35: =IF(ROW()-1<=12, INDEX($B$63:$M$63, 1, ROW()-1), IF(ROW()-1<=24, INDEX($P$63:$AA$63, 1, ROW()-1-12), INDEX($AD$63:$AO$63, 1, ROW()-1-24))) -> 133304.17 | L35: =C35-K35 -> 1505861.5
A36: 2028-04-30 | B36: =B35 * (1 + Assumptions!$B$13) -> 1579752.1 | C36: =G36 * (Assumptions!$B$4 * Assumptions!$B$19 + Assumptions!$B$5 / 12 * Assumptions!$B$20) + H36 * (Assumptions!$B$6 * Assumptions!$B$19 + Assumptions!$B$7 / 12 * Assumptions!$B$20) -> 1776307.8 | D36: =B36 * (Assumptions!$B$14) -> 7898.7603 | E36: =D36 * (Assumptions!$B$15) -> 1579.7521 | F36: =D36 * (Assumptions!$B$16) -> 394.93802 | G36: =G35 * (1 - Assumptions!$B$17) + E36 -> 15242.786 | H36: =H35 * (1 - Assumptions!$B$18) + F36 -> 4298.5263 | I36: =IF(ROW()-1<=12, INDEX($B$52:$M$52, 1, ROW()-1), IF(ROW()-1<=24, INDEX($P$52:$AA$52, 1, ROW()-1-12), INDEX($AD$52:$AO$52, 1, ROW()-1-24))) -> 115104.17 | J36: =$AD$61 -> 18200 | K36: =IF(ROW()-1<=12, INDEX($B$63:$M$63, 1, ROW()-1), IF(ROW()-1<=24, INDEX($P$63:$AA$63, 1, ROW()-1-12), INDEX($AD$63:$AO$63, 1, ROW()-1-24))) -> 133304.17 | L36: =C36-K36 -> 1643003.7
A37: 2028-05-31 | B37: =B36 * (1 + Assumptions!$B$13) -> 1690334.7 | C37: =G37 * (Assumptions!$B$4 * Assumptions!$B$19 + Assumptions!$B$5 / 12 * Assumptions!$B$20) + H37 * (Assumptions!$B$6 * Assumptions!$B$19 + Assumptions!$B$7 / 12 * Assumptions!$B$20) -> 1922595.7 | D37: =B37 * (Assumptions!$B$14) -> 8451.6736 | E37: =D37 * (Assumptions!$B$15) -> 1690.3347 | F37: =D37 * (Assumptions!$B$16) -> 422.58368 | G37: =G36 * (1 - Assumptions!$B$17) + E37 -> 16475.837 | H37: =H36 * (1 - Assumptions!$B$18) + F37 -> 4656.6321 | I37: =IF(ROW()-1<=12, INDEX($B$52:$M$52, 1, ROW()-1), IF(ROW()-1<=24, INDEX($P$52:$AA$52, 1, ROW()-1-12), INDEX($AD$52:$AO$52, 1, ROW()-1-24))) -> 115104.17 | J37: =$AD$61 -> 18200 | K37: =IF(ROW()-1<=12, INDEX($B$63:$M$63, 1, ROW()-1), IF(ROW()-1<=24, INDEX($P$63:$AA$63, 1, ROW()-1-12), INDEX($AD$63:$AO$63, 1, ROW()-1-24))) -> 133304.17 | L37: =C37-K37 -> 1789291.6
A41: OPERATING EXPENSES (OPEX) | B41: Year 1 | P41: Year 2 | AD41: Year 3
B42: Month 1 | C42: Month 2 | D42: Month 3 | E42: Month 4 | F42: Month 5 | G42: Month 6 | H42: Month 7 | I42: Month 8 | J42: Month 9 | K42: Month 10 | L42: Month 11 | M42: Month 12 | P42: Month 1 | Q42: Month 2 | R42: Month 3 | S42: Month 4 | T42: Month 5 | U42: Month 6 | V42: Month 7 | W42: Month 8 | X42: Month 9 | Y42: Month 10 | Z42: Month 11 | AA42: Month 12 | AD42: Month 1 | AE42: Month 2 | AF42: Month 3 | AG42: Month 4 | AH42: Month 5 | AI42: Month 6 | AJ42: Month 7 | AK42: Month 8 | AL42: Month 9 | AM42: Month 10 | AN42: Month 11 | AO42: Month 12
A43: Personnel Costs
...

Sheet Cash Flow & Runway
A1: Cash Flow Table | B1: Month 1 | C1: Month 2 | D1: Month 3 | E1: Month 4 | F1: Month 5 | G1: Month 6 | H1: Month 7 | I1: Month 8 | J1: Month 9 | K1: Month 10 | L1: Month 11 | M1: Month 12 | N1: Month 13 | O1: Month 14 | P1: Month 15 | Q1: Month 16 | R1: Month 17 | S1: Month 18 | T1: Month 19 | U1: Month 20 | V1: Month 21 | W1: Month 22 | X1: Month 23 | Y1: Month 24 | Z1: Month 25 | AA1: Month 26 | AB1: Month 27 | AC1: Month 28 | AD1: Month 29 | AE1: Month 30 | AF1: Month 31 | AG1: Month 32 | AH1: Month 33 | AI1: Month 34 | AJ1: Month 35 | AK1: Month 36
A2: Opening Cash Balance | B2: 0 | C2: =B15 -> 85228.75 | D2: =C15 -> 75704.898 | E2: =D15 -> 72122.899 | F2: =E15 -> 75283.499 | G2: =F15 -> 86109.623 | H2: =G15 -> 827435.48 | I2: =H15 -> 883315.1 | J2: =I15 -> 1060985 | ... R2: =Q15 -> 3508694.2
A3: Cash Inflows
A4: SaaS Revenue collected | B4: {=TRANSPOSE('SaaS - Model'!C2:C37)} -> 5426.6667 | C4: 11551.408 | D4: 18481.711 | E4: 26341.11 | F4: 35271.603 | G4: 45436.414 | H4: 57023.188 | I4: 70247.651 | J4: 85357.822 | K4: 102638.87 | L4: 122418.66 | M4: 145074.2 | N4: 169776.64 | O4: 196735.81 | P4: 226182.42 | Q4: 258370.09 | R4: 293577.7 | S4: 332111.88 | T4: 374309.81 | U4: 420542.28 | V4: 471217.01 | W4: 526782.44 | X4: 587731.69 | Y4: 654607.14 | Z4: 728005.26 | AA4: 805967.32 | AB4: 888826.2 | AC4: 976937.77 | AD4: 1070682.4 | AE4: 1170466.9 | AF4: 1276726.1 | AG4: 1389925.1 | AH4: 1510561 | AI4: 1639165.7 | AJ4: 1776307.8 | AK4: 1922595.7
A5: Enterprise Revenue collected | B5: 0 | C5: 0 | D5: 0 | E5: 0 | F5: 0 | G5: ='Enterprise Solutions'!B64 -> 0 | H5: ='Enterprise Solutions'!C64 -> 75600 | I5: ='Enterprise Solutions'!D64 -> 201600 | J5: ='Enterprise Solutions'!E64 -> 277200 | K5: ='Enterprise Solutions'!F64 -> 201600 | L5: ='Enterprise Solutions'!G64 -> 277200 | M5: ='Enterprise Solutions'!H64 -> 327600 | N5: ='Enterprise Solutions'!I64 -> 277200 | ... R5: ='Enterprise Solutions'!M64 -> 277200 | S5: Enterprise proven, need to review strategy
A6: Funding Received | B6: 100000 | C6: 0 | D6: 0 | E6: 0 | F6: 0 | G6: 750000
A8: Cash Outflows
A9: SaaS COGS | B9: {=TRANSPOSE('SaaS - Model'!G2:G37 + 'SaaS - Model'!H2:H37) * (Assumptions!$B$54 + Assumptions!$B$55)} -> 781.25 | C9: 1658.5938 | D9: 2647.043 | E9: 3763.8437 | F9: 5028.8121 | G9: 6464.7203 | H9: 8097.7403 | I9: 9957.9544 | J9: 12079.943 | K9: 14503.457 | L9: 17274.198 | M9: 20444.709 | N9: 23893.666 | O9: 27650.002 | P9: 31745.51 | Q9: 36215.133 | R9: 41097.279 | S9: 46434.167 | T9: 52272.21 | U9: 58662.435 | V9: 65660.947 | W9: 73329.434 | X9: 81735.727 | Y9: 90954.419 | Z9: 101067.54 | AA9: 111788.85 | AB9: 123163.73 | AC9: 135240.66 | AD9: 148071.41 | AE9: 161711.32 | AF9: 176219.53 | AG9: 191659.22 | AH9: 208097.96 | AI9: 225607.95 | AJ9: 244266.41 | AK9: 264155.87
A10: Enterprise Direct Costs | B10: 0 | C10: 0 | D10: 0 | E10: 0 | F10: 0 | G10: {='Enterprise Solutions'!B84:M84} -> €0 | H10: 21000 | I10: 36574 | J10: 57574 | K10: 57574 | L10: 57574 | M10: 43294 | N10: 64294 | O10: 64294 | P10: 57574 | Q10: 43294 | R10: 64294 | S10: Enterprise proven, need to review strategy
A11: Total Personnel Costs | B11: =SUM('SaaS - Model'!B49:B50) -> 12916.667 | C11: =SUM('SaaS - Model'!C49:C50) -> 12916.667 | D11: =SUM('SaaS - Model'!D49:D50) -> 12916.667 | E11: =SUM('SaaS - Model'!E49:E50) -> 12916.667 | F11: =SUM('SaaS - Model'!F49:F50) -> 12916.667 | G11: {=TRANSPOSE('SaaS - Model'!I2:I37)} -> 41145.833 | H11: 41145.833 | I11: 41145.833 | J11: 41145.833 | K11: 41145.833 | L11: 41145.833 | M11: 41145.833 | N11: 41145.833 | O11: 41145.833 | P11: 41145.833 | Q11: 41145.833 | R11: 41145.833 | S11: 73958.333 | T11: 73958.333 | U11: 73958.333 | V11: 73958.333 | W11: 73958.333 | X11: 73958.333 | Y11: 73958.333 | Z11: 73958.333 | AA11: 73958.333 | AB11: 73958.333 | AC11: 73958.333 | AD11: 73958.333 | AE11: 115104.17 | AF11: 115104.17 | AG11: 115104.17 | AH11: 115104.17 | AI11: 115104.17 | AJ11: 115104.17 | AK11: 115104.17 | AL11: 115104.17 | AM11: 115104.17 | AN11: 115104.17 | AO11: 115104.17 | AP11: 115104.17
A12: Total other OPEX | B12: {=TRANSPOSE('SaaS - Model'!J2:J37)} -> 6500 | C12: 6500 | D12: 6500 | E12: 6500 | F12: 6500 | G12: 6500 | H12: 6500 | I12: 6500 | J12: 6500 | K12: 6500 | L12: 6500 | M12: 6500 | N12: 6500 | O12: 11700 | P12: 11700 | Q12: 11700 | R12: 11700 | S12: 11700 | T12: 11700 | U12: 11700 | V12: 11700 | W12: 11700 | X12: 11700 | Y12: 11700 | Z12: 11700 | AA12: 18200 | AB12: 18200 | AC12: 18200 | AD12: 18200 | AE12: 18200 | AF12: 18200 | AG12: 18200 | AH12: 18200 | AI12: 18200 | AJ12: 18200 | AK12: 18200
A14: Net Cash Flow for the Month | B14: =(B4+B5+B6) - (B9+B10+B11+B12) -> 85228.75 | C14: =(C4+C5+C6) - (C9+C10+C11+C12) -> -9523.8521 | D14: =(D4+D5+D6) - (D9+D10+D11+D12) -> -3581.9988 | E14: =(E4+E5+E6) - (E9+E10+E11+E12) -> 3160.6 | F14: =(F4+F5+F6) - (F9+F10+F11+F12) -> 10826.124 | G14: =(G4+G5+G6) - (G9+G10+G11+G12) -> 741325.86 | H14: =(H4+H5+H6) - (H9+H10+H11+H12) -> 55879.615 | I14: =(I4+I5+I6) - (I9+I10+I11+I12) -> 177669.86 | ... R14: =(R4+R5+R6) - (R9+R10+R11+R12) -> 412540.59
A15: Closing Cash Balance | B15: =B2+B14 -> 85228.75 | C15: =C2+C14 -> 75704.898 | D15: =D2+D14 -> 72122.899 | E15: =E2+E14 -> 75283.499 | F15: =F2+F14 -> 86109.623 | G15: =G2+G14 -> 827435.48 | H15: =H2+H14 -> 883315.1 | I15: =I2+I14 -> 1060985 | ... R15: =R2+R14 -> 3921234.8
A17: Runway Calculation
A18: Monthly Cash Burn | B18: =IF(B14<0, -B14, 0) -> 0 | C18: =IF(C14<0, -C14, 0) -> 9523.8521 | D18: =IF(D14<0, -D14, 0) -> 3581.9988 | E18: =IF(E14<0, -E14, 0) -> 0 | F18: =IF(F14<0, -F14, 0) -> 0 | G18: =IF(G14<0, -G14, 0) -> 0 | H18: =IF(H14<0, -H14, 0) -> 0 | I18: =IF(I14<0, -I14, 0) -> 0 | ... R18: =IF(R14<0, -R14, 0) -> 0
A19: Runway (in month) | B19: =IF(B18>0, B15/B18, "N/A") -> N/A | C19: =IF(C18>0, C15/C18, "N/A") -> 7.9489788 | D19: =IF(D20>0, D15/D20, "N/A") -> N/A | E19: =IF(E18>0, E15/E18, "N/A") -> N/A | F19: =IF(F18>0, F15/F18, "N/A") -> N/A | G19: =IF(G18>0, G15/G18, "N/A") -> N/A | H19: =IF(H18>0, H15/H18, "N/A") -> N/A | I19: =IF(I18>0, I15/I18, "N/A") -> N/A | J19: =IF(J18>0, J15/J18, "N/A") -> N/A | K19: =IF(K18>0, K15/K18, "N/A") -> N/A | L19: =IF(L18>0, L15/L18, "N/A") -> N/A | ... R19: =IF(R18>0, R15/R18, "N/A") -> N/A

Sheet Yearly KPIs
B1: Month | C1: Revenue | D1: Total_Costs | E1: EBITDA | F1: Users | G1: Gross_Margin | H1: EBITDA_Margin
A2: 0 | B2: 2025-12-31 | C2: 1245.01 | D2: 404314.75 | E2: -403069.74 | F2: 2313.06 | G2: -6611.11 | H2: -34450.98
A3: 1 | B3: 2026-12-31 | C3: 7728.03 | D3: 1285438.8 | E3: -1277710.8 | F3: 9478.29 | G3: -6611.11 | H3: -17225.36
A4: 2 | B4: 2027-12-31 | C4: 23508.61 | D4: 2774699.6 | E4: -2751191 | F4: 25199.33 | G4: -6611.11 | H4: -11841.05
A5: 3 | B5: 2028-12-31 | C5: 17444.11 | D5: 1751371 | E5: -1733926.9 | F5: 35343.36 | G5: -6611.11 | H5: -9970.48
